Workbook

Sheet Sheet1
A1: GENERIC | D1: BRAND NAMES | E1: EXPIRY
A2: ANASTROZOLE | C2: 30 | D2: Anatero
C3: 28 | D3: Arimidex
C4: 30 | D4: Armida
C5: 30 | D5: Fobrecane
C6: 28 | D6: Macrozole
C7: 30 | D7: Vexal-a
A9: LETROZOLE | C9: 30 | D9: Femara
C10: 30 | D10: Letoripe
C11: 30 | D11: Mamazol
C12: 30 | D12: Medrozole
C13: 30 | D13: Ovalia
C14: 30 | D14: Wanda
A16: CAPECITABINE | C16: 100 | D16: Capetero
C17: 100 | D17: Capomed
C18: 60 | D18: Celabin
C19: 100 | D19: Naprocap
A21: TACROLIMUS | C21: 50 | D21: Advagraf
C22: 60 | D22: Limast
C23: 60 | D23: Meditrina
C24: 50 | D24: Prograf
C25: 50 | D25: Tacromax
A27: CICLOSPORIN | C27: 50 | D27: Arpimune
D28: Ikervis
C29: 50 | D29: Neoral Sandimmum 100
C30: 50 | D30: Neoral Sandimmum 25
A32: MYCOPHENOLATE | C32: 50 | D32: Atajec 500
C33: 50 | D33: Cellcept 500
C34: 50 | D34: Hocept 500
C35: 30 | D35: Mycept 250
C36: 30 | D36: Mycept 500
C37: 120 | D37: Myfortic 360
C38: 30 | D38: Mysod 360
C39: 10 | D39: Navaxif 500
A41: ALENDRONIC ACID | C41: 4 | D41: Aldren
C42: 4 | D42: Alendra
C43: 4 | D43: Alovell
C44: 4 | D44: Binosto
D45: Bondros
C46: 2 | D46: Fosavance
...

Sheet Sheet2

Sheet Medicines
A1: Medicine Name | B1: Batch No. | C1: Expiration Date | D1: Exp Year | E1: Exp Month
D2: =YEAR(C2 ) -> 1899 | E2: =MONTH(C2 ) -> 12
D3: =YEAR(C3 ) -> 1899 | E3: =MONTH(C3 ) -> 12
D4: =YEAR(C4 ) -> 1899 | E4: =MONTH(C4 ) -> 12
D5: =YEAR(C5 ) -> 1899 | E5: =MONTH(C5 ) -> 12
D6: =YEAR(C6 ) -> 1899 | E6: =MONTH(C6 ) -> 12
D7: =YEAR(C7 ) -> 1899 | E7: =MONTH(C7 ) -> 12
D8: =YEAR(C8 ) -> 1899 | E8: =MONTH(C8 ) -> 12
D9: =YEAR(C9 ) -> 1899 | E9: =MONTH(C9 ) -> 12
D10: =YEAR(C10 ) -> 1899 | E10: =MONTH(C10 ) -> 12
D11: =YEAR(C11 ) -> 1899 | E11: =MONTH(C11 ) -> 12
D12: =YEAR(C12 ) -> 1899 | E12: =MONTH(C12 ) -> 12
D13: =YEAR(C13 ) -> 1899 | E13: =MONTH(C13 ) -> 12
... D21: =YEAR(C21 ) -> 1899 | E21: =MONTH(C21 ) -> 12

Sheet 2026 Summary
A1: Month | B1: No. of Medicines Expiring in 2026 | D1: Formula Used
A2: January | B2: =COUNTIFS(Medicines!$D:$D,2026,Medicines!$E:$E,1) -> 0 | D2: =COUNTIFS(Medicines!$D:$D,2026,Medicines!$E:$E,1) -> 0
A3: February | B3: =COUNTIFS(Medicines!$D:$D,2026,Medicines!$E:$E,2) -> 0 | D3: =COUNTIFS(Medicines!$D:$D,2026,Medicines!$E:$E,2) -> 0
A4: March | B4: =COUNTIFS(Medicines!$D:$D,2026,Medicines!$E:$E,3) -> 0 | D4: =COUNTIFS(Medicines!$D:$D,2026,Medicines!$E:$E,3) -> 0
A5: April | B5: =COUNTIFS(Medicines!$D:$D,2026,Medicines!$E:$E,4) -> 0 | D5: =COUNTIFS(Medicines!$D:$D,2026,Medicines!$E:$E,4) -> 0
A6: May | B6: =COUNTIFS(Medicines!$D:$D,2026,Medicines!$E:$E,5) -> 0 | D6: =COUNTIFS(Medicines!$D:$D,2026,Medicines!$E:$E,5) -> 0
A7: June | B7: =COUNTIFS(Medicines!$D:$D,2026,Medicines!$E:$E,6) -> 0 | D7: =COUNTIFS(Medicines!$D:$D,2026,Medicines!$E:$E,6) -> 0
A8: July | B8: =COUNTIFS(Medicines!$D:$D,2026,Medicines!$E:$E,7) -> 0 | D8: =COUNTIFS(Medicines!$D:$D,2026,Medicines!$E:$E,7) -> 0
A9: August | B9: =COUNTIFS(Medicines!$D:$D,2026,Medicines!$E:$E,8) -> 0 | D9: =COUNTIFS(Medicines!$D:$D,2026,Medicines!$E:$E,8) -> 0
A10: September | B10: =COUNTIFS(Medicines!$D:$D,2026,Medicines!$E:$E,9) -> 0 | D10: =COUNTIFS(Medicines!$D:$D,2026,Medicines!$E:$E,9) -> 0
A11: October | B11: =COUNTIFS(Medicines!$D:$D,2026,Medicines!$E:$E,10) -> 0 | D11: =COUNTIFS(Medicines!$D:$D,2026,Medicines!$E:$E,10) -> 0
A12: November | B12: =COUNTIFS(Medicines!$D:$D,2026,Medicines!$E:$E,11) -> 0 | D12: =COUNTIFS(Medicines!$D:$D,2026,Medicines!$E:$E,11) -> 0
A13: December | B13: =COUNTIFS(Medicines!$D:$D,2026,Medicines!$E:$E,12) -> 0 | D13: =COUNTIFS(Medicines!$D:$D,2026,Medicines!$E:$E,12) -> 0
